Workbook

Sheet W1
N1: 45323 | R1: 45324
A3: Inquiry/Response | B3: Email | C3: Phone | D3: In-per | E3: D-Total | F3: Email | G3: Phone | H3: In-per | I3: D-Total | J3: Email | K3: Phone | L3: In-per | M3: D-Total | N3: Email | O3: Phone | P3: In-per | Q3: D-Total | R3: Email | S3: Phone | T3: In-per | U3: D-Total | V3: Prim-Catgry Tot | W3: Categories
A4: Academic Advising Appointments | E4: =sum(B4:D4) -> 0 | I4: =sum(F4:H4) -> 0 | M4: =sum(J4:L4) -> 0 | Q4: =sum(N4:P4) -> 0 | U4: =sum(R4:T4) -> 0 | V4: =sum(E4,I4,M4,Q4,U4) -> 0 | W4: Academics
A5: Academic Consideration Requests (ACRs) - Missing Classes | E5: =sum(B5:D5) -> 0 | I5: =sum(F5:H5) -> 0 | M5: =sum(J5:L5) -> 0 | Q5: =sum(N5:P5) -> 0 | U5: =sum(R5:T5) -> 0 | V5: =sum(E5,I5,M5,Q5,U5) -> 0 | W5: Academics | Y5: Main Catergories Analysis | Z5: #'s | AG5: Top 5 Categories
A6: Academic Standing | E6: =sum(B6:D6) -> 0 | I6: =sum(F6:H6) -> 0 | M6: =sum(J6:L6) -> 0 | Q6: =sum(N6:P6) -> 0 | R6: 1 | U6: =sum(R6:T6) -> 1 | V6: =sum(E6,I6,M6,Q6,U6) -> 1 | W6: Academics | Y6: Academics | Z6: =SUMIF(W:W,"Academics",V:V) -> 22 | AH6: Inquiry | AI6: Amount
A7: Access Centre/Academic Accomodation Support | E7: =sum(B7:D7) -> 0 | I7: =sum(F7:H7) -> 0 | M7: =sum(J7:L7) -> 0 | Q7: =sum(N7:P7) -> 0 | U7: =sum(R7:T7) -> 0 | V7: =sum(E7,I7,M7,Q7,U7) -> 0 | W7: Academics | Y7: Referral | Z7: =SUMIF(W:W,"Referral",V:V) -> 7 | AG7: 1 | AH7: {=IFERROR(TEXTJOIN(", ", TRUE, IF($V$4:$V$84=AI7, $A$4:$A$84, "")), "")} -> Course Enrollment | AI7: =LARGE($V$4:$V$84,1) -> 8
A8: ACES | E8: =sum(B8:D8) -> 0 | I8: =sum(F8:H8) -> 0 | M8: =sum(J8:L8) -> 0 | Q8: =sum(N8:P8) -> 0 | U8: =sum(R8:T8) -> 0 | V8: =sum(E8,I8,M8,Q8,U8) -> 0 | W8: Academics | Y8: Financial | Z8: =SUMIF(W:W,"Financial",V:V) -> 2 | AG8: 2 | AH8: {=IFERROR(TEXTJOIN(", ", TRUE, IF($V$4:$V$84=AI8, $A$4:$A$84, "")), "")} -> Chang School | AI8: {=LARGE(IF($V$4:$V$84<>MAX($AI$7:AI7),$V$4:$V$84),1)} -> 4
A9: Admissions | E9: =sum(B9:D9) -> 0 | I9: =sum(F9:H9) -> 0 | M9: =sum(J9:L9) -> 0 | Q9: =sum(N9:P9) -> 0 | R9: 1 | U9: =sum(R9:T9) -> 1 | V9: =sum(E9,I9,M9,Q9,U9) -> 1 | W9: Referral | Y9: Mental Health and Wellness | Z9: =SUMIF(W:W, "Mental Health and Wellness", V:V) -> 0 | AG9: 3 | AH9: {=IFERROR(TEXTJOIN(", ", TRUE, IF($V$4:$V$84=AI9, $A$4:$A$84, "")), "")} -> Engineering Program Transition Courses | AI9: {=LARGE(IF($V$4:$V$84<>MAX($AI$7:AI7),IF($V$4:$V$84<>MAX($AI$8:AI8),$V$4:$V$84)),1)} -> 3
A10: Advisement Report | E10: =sum(B10:D10) -> 0 | I10: =sum(F10:H10) -> 0 | M10: =sum(J10:L10) -> 0 | Q10: =sum(N10:P10) -> 0 | U10: =sum(R10:T10) -> 0 | V10: =sum(E10,I10,M10,Q10,U10) -> 0 | W10: Academics | Y10: Other | Z10: =SUMIF(W:W, "Other", V:V) -> 5 | AG10: 4 | AH10: {=IFERROR(TEXTJOIN(", ", TRUE, IF($V$4:$V$84=AI10, $A$4:$A$84, "")), "")} -> Directions, Supplies Request, e.g. stapler, scissor, etc, Wait List | AI10: {=LARGE(IF($V$4:$V$84<>MAX($AI$7:AI7), IF($V$4:$V$84<>MAX($AI$8:AI8), IF($V$4:$V$84<>MAX($AI$9:AI9), $V$4:$V$84))), 1)} -> 2
A11: Appeals | E11: =sum(B11:D11) -> 0 | I11: =sum(F11:H11) -> 0 | M11: =sum(J11:L11) -> 0 | Q11: =sum(N11:P11) -> 0 | U11: =sum(R11:T11) -> 0 | V11: =sum(E11,I11,M11,Q11,U11) -> 0 | W11: Referral | AG11: 5 | AH11: {=IFERROR(TEXTJOIN(", ", TRUE, IF($V$4:$V$84=AI11, $A$4:$A$84, "")), "")} -> Academic Standing, Admissions, CEN100, Exams/Mid-Terms, Fees, OSAP, OSMS/OSEIE, Other, Plan Change, Probation Contract, Probationary Standing, Required to Withdraw (RTW), Retroactive Course Drop, Service Hub, Upper Year Students | AI11: {=LARGE(IF($V$4:$V$84<>MAX($AI$7:AI7), IF($V$4:$V$84<>MAX($AI$8:AI8), IF($V$4:$V$84<>MAX($AI$9:AI9), IF($V$4:$V$84<>MAX($AI$10:AI10), $V$4:$V$84)))), 1)} -> 1
A12: Awards/Scholarships | E12: =sum(B12:D12) -> 0 | I12: =sum(F12:H12) -> 0 | M12: =sum(J12:L12) -> 0 | Q12: =sum(N12:P12) -> 0 | U12: =sum(R12:T12) -> 0 | V12: =sum(E12,I12,M12,Q12,U12) -> 0 | W12: Referral
A13: Building and Campus access | E13: =sum(B13:D13) -> 0 | I13: =sum(F13:H13) -> 0 | M13: =sum(J13:L13) -> 0 | Q13: =sum(N13:P13) -> 0 | U13: =sum(R13:T13) -> 0 | V13: =sum(E13,I13,M13,Q13,U13) -> 0 | W13: Referral | Y13: Inquiry Breakdown For Week
A14: Careers/Employment | E14: =sum(B14:D14) -> 0 | I14: =sum(F14:H14) -> 0 | M14: =sum(J14:L14) -> 0 | Q14: =sum(N14:P14) -> 0 | U14: =sum(R14:T14) -> 0 | V14: =sum(E14,I14,M14,Q14,U14) -> 0 | W14: Referral | Z14: Monday | AA14: Tuesday | AB14: Wednesday | AC14: Thursday | AD14: Friday | AE14: Method
A15: CCS/Student Help Desk | E15: =sum(B15:D15) -> 0 | I15: =sum(F15:H15) -> 0 | M15: =sum(J15:L15) -> 0 | Q15: =sum(N15:P15) -> 0 | U15: =sum(R15:T15) -> 0 | V15: =sum(E15,I15,M15,Q15,U15) -> 0 | W15: Referral | Y15: Email | Z15: =B85 -> 0 | AA15: =F85 -> 0 | AB15: =J85 -> 0 | AC15: =N85 -> 5 | AD15: =R85 -> 6 | AE15: =sum(Z15:AD15) -> 11
A16: CEN100 | E16: =sum(B16:D16) -> 0 | I16: =sum(F16:H16) -> 0 | M16: =sum(J16:L16) -> 0 | N16: 1 | Q16: =sum(N16:P16) -> 1 | U16: =sum(R16:T16) -> 0 | V16: =sum(E16,I16,M16,Q16,U16) -> 1 | W16: Academics | Y16: Phone | Z16: =C85 -> 0 | AA16: =G85 -> 0 | AB16: =K85 -> 0 | AC16: =O85 -> 0 | AD16: =S85 -> 0 | AE16: =sum(Z16:AD16) -> 0
A17: Chang School | E17: =sum(B17:D17) -> 0 | I17: =sum(F17:H17) -> 0 | M17: =sum(J17:L17) -> 0 | P17: 2 | Q17: =sum(N17:P17) -> 2 | T17: 2 | U17: =sum(R17:T17) -> 2 | V17: =sum(E17,I17,M17,Q17,U17) -> 4 | W17: Referral | Y17: In-Person | Z17: =B86 | AA17: =F86 | AB17: =J86 | AC17: =N86 -> 11 | AD17: =R86 -> 14 | AE17: =sum(Z17:AD17) -> 25
A18: Computer Labs | E18: =sum(B18:D18) -> 0 | I18: =sum(F18:H18) -> 0 | M18: =sum(J18:L18) -> 0 | Q18: =sum(N18:P18) -> 0 | U18: =sum(R18:T18) -> 0 | V18: =sum(E18,I18,M18,Q18,U18) -> 0 | W18: Referral | Y18: Inquiry Breakdown | Z18: =sum(Z15:Z17) -> 0 | AA18: =sum(AA15:AA17) -> 0 | AB18: =sum(AB15:AB17) -> 0 | AC18: =sum(AC15:AC17) -> 16 | AD18: =sum(AD15:AD17) -> 20 | AE18: =sum(Z18:AD18) -> 36
A19: Contact Info Requests | E19: =sum(B19:D19) -> 0 | I19: =sum(F19:H19) -> 0 | M19: =sum(J19:L19) -> 0 | Q19: =sum(N19:P19) -> 0 | U19: =sum(R19:T19) -> 0 | V19: =sum(E19,I19,M19,Q19,U19) -> 0 | W19: Referral
A20: Coop | E20: =sum(B20:D20) -> 0 | I20: =sum(F20:H20) -> 0 | M20: =sum(J20:L20) -> 0 | Q20: =sum(N20:P20) -> 0 | U20: =sum(R20:T20) -> 0 | V20: =sum(E20,I20,M20,Q20,U20) -> 0 | W20: Referral
A21: Counselling Centre Appointments | E21: =sum(B21:D21) -> 0 | I21: =sum(F21:H21) -> 0 | M21: =sum(J21:L21) -> 0 | Q21: =sum(N21:P21) -> 0 | U21: =sum(R21:T21) -> 0 | V21: =sum(E21,I21,M21,Q21,U21) -> 0 | W21: Mental Health and Wellness | Y21: Inquiry Timings - Monday
A22: Course Delivery | E22: =sum(B22:D22) -> 0 | I22: =sum(F22:H22) -> 0 | M22: =sum(J22:L22) -> 0 | Q22: =sum(N22:P22) -> 0 | U22: =sum(R22:T22) -> 0 | V22: =sum(E22,I22,M22,Q22,U22) -> 0 | W22: Referral | Y22: Time | Z22: Number of People | AA22: Topic of inquiries | AB22: Phone | AC22: In-Person
A23: Course Drop | E23: =sum(B23:D23) -> 0 | I23: =sum(F23:H23) -> 0 | M23: =sum(J23:L23) -> 0 | Q23: =sum(N23:P23) -> 0 | U23: =sum(R23:T23) -> 0 | V23: =sum(E23,I23,M23,Q23,U23) -> 0 | W23: Academics | Y23: 45179 | AB23: FALSE | AC23: FALSE
A24: Course Enrollment | E24: =sum(B24:D24) -> 0 | I24: =sum(F24:H24) -> 0 | M24: =sum(J24:L24) -> 0 | P24: 4 | Q24: =sum(N24:P24) -> 4 | R24: 1 | T24: 3 | U24: =sum(R24:T24) -> 4 | V24: =sum(E24,I24,M24,Q24,U24) -> 8 | W24: Academics | Y24: 45210 | AB24: FALSE | AC24: FALSE
A25: Course Intentions | E25: =sum(B25:D25) -> 0 | I25: =sum(F25:H25) -> 0 | M25: =sum(J25:L25) -> 0 | Q25: =sum(N25:P25) -> 0 | U25: =sum(R25:T25) -> 0 | V25: =sum(E25,I25,M25,Q25,U25) -> 0 | W25: Academics | Y25: 45242 | AB25: FALSE | AC25: FALSE
A26: Course Outlines | E26: =sum(B26:D26) -> 0 | I26: =sum(F26:H26) -> 0 | M26: =sum(J26:L26) -> 0 | Q26: =sum(N26:P26) -> 0 | U26: =sum(R26:T26) -> 0 | V26: =sum(E26,I26,M26,Q26,U26) -> 0 | W26: Referral | Y26: 45261 | AB26: FALSE | AC26: FALSE
A27: Course Planning/Course Load management | E27: =sum(B27:D27) -> 0 | I27: =sum(F27:H27) -> 0 | M27: =sum(J27:L27) -> 0 | Q27: =sum(N27:P27) -> 0 | U27: =sum(R27:T27) -> 0 | V27: =sum(E27,I27,M27,Q27,U27) -> 0 | W27: Academics | Y27: 44928 | AB27: FALSE | AC27: FALSE
A28: Course Swap | E28: =sum(B28:D28) -> 0 | I28: =sum(F28:H28) -> 0 | M28: =sum(J28:L28) -> 0 | Q28: =sum(N28:P28) -> 0 | U28: =sum(R28:T28) -> 0 | V28: =sum(E28,I28,M28,Q28,U28) -> 0 | W28: Academics | Y28: 44960 | AB28: FALSE | AC28: FALSE
A29: D2L | E29: =sum(B29:D29) -> 0 | I29: =sum(F29:H29) -> 0 | M29: =sum(J29:L29) -> 0 | Q29: =sum(N29:P29) -> 0 | U29: =sum(R29:T29) -> 0 | V29: =sum(E29,I29,M29,Q29,U29) -> 0 | W29: Academics | Y29: 44989 | AB29: FALSE | AC29: FALSE
A30: Directions | E30: =sum(B30:D30) -> 0 | I30: =sum(F30:H30) -> 0 | M30: =sum(J30:L30) -> 0 | Q30: =sum(N30:P30) -> 0 | T30: 2 | U30: =sum(R30:T30) -> 2 | V30: =sum(E30,I30,M30,Q30,U30) -> 2 | W30: Other
A31: Discipline | E31: =sum(B31:D31) -> 0 | I31: =sum(F31:H31) -> 0 | M31: =sum(J31:L31) -> 0 | Q31: =sum(N31:P31) -> 0 | U31: =sum(R31:T31) -> 0 | V31: =sum(E31,I31,M31,Q31,U31) -> 0 | W31: Referral
A32: Early Intervention | E32: =sum(B32:D32) -> 0 | I32: =sum(F32:H32) -> 0 | M32: =sum(J32:L32) -> 0 | Q32: =sum(N32:P32) -> 0 | U32: =sum(R32:T32) -> 0 | V32: =sum(E32,I32,M32,Q32,U32) -> 0 | W32: Academics | Y32: Inquiry Timings - Tuesday
A33: Engineering Program Transition Courses | E33: =sum(B33:D33) -> 0 | I33: =sum(F33:H33) -> 0 | M33: =sum(J33:L33) -> 0 | N33: 1 | P33: 2 | Q33: =sum(N33:P33) -> 3 | U33: =sum(R33:T33) -> 0 | V33: =sum(E33,I33,M33,Q33,U33) -> 3 | W33: Academics | Y33: Time | Z33: Number of People | AA33: Topic of inquiries | AB33: Phone | AC33: In-Person
A34: Enrollment Period | E34: =sum(B34:D34) -> 0 | I34: =sum(F34:H34) -> 0 | M34: =sum(J34:L34) -> 0 | Q34: =sum(N34:P34) -> 0 | U34: =sum(R34:T34) -> 0 | V34: =sum(E34,I34,M34,Q34,U34) -> 0 | W34: Academics | Y34: 45179 | AB34: FALSE | AC34: FALSE
A35: Exams/Mid-Terms | E35: =sum(B35:D35) -> 0 | I35: =sum(F35:H35) -> 0 | M35: =sum(J35:L35) -> 0 | Q35: =sum(N35:P35) -> 0 | R35: 1 | U35: =sum(R35:T35) -> 1 | V35: =sum(E35,I35,M35,Q35,U35) -> 1 | W35: Academics | Y35: 45210 | AB35: FALSE | AC35: FALSE
A36: Fees | E36: =sum(B36:D36) -> 0 | I36: =sum(F36:H36) -> 0 | M36: =sum(J36:L36) -> 0 | P36: 1 | Q36: =sum(N36:P36) -> 1 | U36: =sum(R36:T36) -> 0 | V36: =sum(E36,I36,M36,Q36,U36) -> 1 | W36: Financial | Y36: 45242 | AB36: FALSE | AC36: FALSE
A37: First Year Ambassador Program | E37: =sum(B37:D37) -> 0 | I37: =sum(F37:H37) -> 0 | M37: =sum(J37:L37) -> 0 | Q37: =sum(N37:P37) -> 0 | U37: =sum(R37:T37) -> 0 | V37: =sum(E37,I37,M37,Q37,U37) -> 0 | W37: Academics | Y37: 45261 | AB37: FALSE | AC37: FALSE
A38: First Year in Two Years | E38: =sum(B38:D38) -> 0 | I38: =sum(F38:H38) -> 0 | M38: =sum(J38:L38) -> 0 | Q38: =sum(N38:P38) -> 0 | U38: =sum(R38:T38) -> 0 | V38: =sum(E38,I38,M38,Q38,U38) -> 0 | W38: Academics | Y38: 44928 | AB38: FALSE | AC38: FALSE
A39: Fresh Start / Reinstatement | E39: =sum(B39:D39) -> 0 | I39: =sum(F39:H39) -> 0 | M39: =sum(J39:L39) -> 0 | Q39: =sum(N39:P39) -> 0 | U39: =sum(R39:T39) -> 0 | V39: =sum(E39,I39,M39,Q39,U39) -> 0 | W39: Academics | Y39: 44960 | AB39: FALSE | AC39: FALSE
A40: General Academic Advising | E40: =sum(B40:D40) -> 0 | I40: =sum(F40:H40) -> 0 | M40: =sum(J40:L40) -> 0 | Q40: =sum(N40:P40) -> 0 | U40: =sum(R40:T40) -> 0 | V40: =sum(E40,I40,M40,Q40,U40) -> 0 | W40: Academics | Y40: 44989 | AB40: FALSE | AC40: FALSE
A41: GPA/CGPA | E41: =sum(B41:D41) -> 0 | I41: =sum(F41:H41) -> 0 | M41: =sum(J41:L41) -> 0 | Q41: =sum(N41:P41) -> 0 | U41: =sum(R41:T41) -> 0 | V41: =sum(E41,I41,M41,Q41,U41) -> 0 | W41: Academics
...

Sheet W2
B1: 45327 | F1: 45328 | J1: 45329 | N1: 45330 | R1: 45331
A3: Inquiry/Response | B3: Email | C3: Phone | D3: In-per | E3: D-Total | F3: Email | G3: Phone | H3: In-per | I3: D-Total | J3: Email | K3: Phone | L3: In-per | M3: D-Total | N3: Email | O3: Phone | P3: In-per | Q3: D-Total | R3: Email | S3: Phone | T3: In-per | U3: D-Total | V3: Prim-Catgry Tot | W3: Categories
A4: Academic Advising Appointments | B4: 1 | E4: =sum(B4:D4) -> 1 | F4: 1 | I4: =sum(F4:H4) -> 1 | M4: =sum(J4:L4) -> 0 | Q4: =sum(N4:P4) -> 0 | U4: =sum(R4:T4) -> 0 | V4: =sum(E4,I4,M4,Q4,U4) -> 2 | W4: Academics
A5: Academic Consideration Requests (ACRs) - Missing Classes | B5: 1 | D5: 1 | E5: =sum(B5:D5) -> 2 | F5: 1 | I5: =sum(F5:H5) -> 1 | J5: 3 | L5: 1 | M5: =sum(J5:L5) -> 4 | N5: 1 | Q5: =sum(N5:P5) -> 1 | R5: 1 | U5: =sum(R5:T5) -> 1 | V5: =sum(E5,I5,M5,Q5,U5) -> 9 | W5: Academics | Y5: Main Catergories Analysis | Z5: #'s | AG5: Top 5 Categories
A6: Academic Standing | E6: =sum(B6:D6) -> 0 | I6: =sum(F6:H6) -> 0 | M6: =sum(J6:L6) -> 0 | Q6: =sum(N6:P6) -> 0 | U6: =sum(R6:T6) -> 0 | V6: =sum(E6,I6,M6,Q6,U6) -> 0 | W6: Academics | Y6: Academics | Z6: =SUMIF(W:W,"Academics",V:V) -> 82 | AH6: Inquiry | AI6: Amount
A7: Access Centre/Academic Accomodation Support | E7: =sum(B7:D7) -> 0 | I7: =sum(F7:H7) -> 0 | M7: =sum(J7:L7) -> 0 | Q7: =sum(N7:P7) -> 0 | U7: =sum(R7:T7) -> 0 | V7: =sum(E7,I7,M7,Q7,U7) -> 0 | W7: Academics | Y7: Referral | Z7: =SUMIF(W:W,"Referral",V:V) -> 44 | AG7: 1 | AH7: {=IFERROR(TEXTJOIN(", ", TRUE, IF($V$4:$V$84=AI7, $A$4:$A$84, "")), "")} -> Engineering Program Transition Courses | AI7: =LARGE($V$4:$V$84,1) -> 21
A8: ACES | E8: =sum(B8:D8) -> 0 | I8: =sum(F8:H8) -> 0 | M8: =sum(J8:L8) -> 0 | Q8: =sum(N8:P8) -> 0 | U8: =sum(R8:T8) -> 0 | V8: =sum(E8,I8,M8,Q8,U8) -> 0 | W8: Academics | Y8: Financial | Z8: =SUMIF(W:W,"Financial",V:V) -> 7 | AG8: 2 | AH8: {=IFERROR(TEXTJOIN(", ", TRUE, IF($V$4:$V$84=AI8, $A$4:$A$84, "")), "")} -> Course Enrollment | AI8: {=LARGE(IF($V$4:$V$84<>MAX($AI$7:AI7),$V$4:$V$84),1)} -> 18
A9: Admissions | B9: 2 | E9: =sum(B9:D9) -> 2 | I9: =sum(F9:H9) -> 0 | L9: 1 | M9: =sum(J9:L9) -> 1 | Q9: =sum(N9:P9) -> 0 | T9: 2 | U9: =sum(R9:T9) -> 2 | V9: =sum(E9,I9,M9,Q9,U9) -> 5 | W9: Referral | Y9: Mental Health and Wellness | Z9: =SUMIF(W:W, "Mental Health and Wellness", V:V) -> 3 | AG9: 3 | AH9: {=IFERROR(TEXTJOIN(", ", TRUE, IF($V$4:$V$84=AI9, $A$4:$A$84, "")), "")} -> Chang School | AI9: {=LARGE(IF($V$4:$V$84<>MAX($AI$7:AI7),IF($V$4:$V$84<>MAX($AI$8:AI8),$V$4:$V$84)),1)} -> 17
A10: Advisement Report | E10: =sum(B10:D10) -> 0 | I10: =sum(F10:H10) -> 0 | M10: =sum(J10:L10) -> 0 | Q10: =sum(N10:P10) -> 0 | U10: =sum(R10:T10) -> 0 | V10: =sum(E10,I10,M10,Q10,U10) -> 0 | W10: Academics | Y10: Other | Z10: =SUMIF(W:W, "Other", V:V) -> 13 | AG10: 4 | AH10: {=IFERROR(TEXTJOIN(", ", TRUE, IF($V$4:$V$84=AI10, $A$4:$A$84, "")), "")} -> Academic Consideration Requests (ACRs) - Missing Classes | AI10: {=LARGE(IF($V$4:$V$84<>MAX($AI$7:AI7), IF($V$4:$V$84<>MAX($AI$8:AI8), IF($V$4:$V$84<>MAX($AI$9:AI9), $V$4:$V$84))), 1)} -> 9
A11: Appeals | D11: 1 | E11: =sum(B11:D11) -> 1 | I11: =sum(F11:H11) -> 0 | L11: 1 | M11: =sum(J11:L11) -> 1 | Q11: =sum(N11:P11) -> 0 | U11: =sum(R11:T11) -> 0 | V11: =sum(E11,I11,M11,Q11,U11) -> 2 | W11: Referral | AG11: 5 | AH11: {=IFERROR(TEXTJOIN(", ", TRUE, IF($V$4:$V$84=AI11, $A$4:$A$84, "")), "")} -> Course Drop, Directions | AI11: {=LARGE(IF($V$4:$V$84<>MAX($AI$7:AI7), IF($V$4:$V$84<>MAX($AI$8:AI8), IF($V$4:$V$84<>MAX($AI$9:AI9), IF($V$4:$V$84<>MAX($AI$10:AI10), $V$4:$V$84)))), 1)} -> 7
A12: Awards/Scholarships | E12: =sum(B12:D12) -> 0 | I12: =sum(F12:H12) -> 0 | M12: =sum(J12:L12) -> 0 | Q12: =sum(N12:P12) -> 0 | U12: =sum(R12:T12) -> 0 | V12: =sum(E12,I12,M12,Q12,U12) -> 0 | W12: Referral
A13: Building and Campus access | E13: =sum(B13:D13) -> 0 | I13: =sum(F13:H13) -> 0 | M13: =sum(J13:L13) -> 0 | Q13: =sum(N13:P13) -> 0 | T13: 1 | U13: =sum(R13:T13) -> 1 | V13: =sum(E13,I13,M13,Q13,U13) -> 1 | W13: Referral | Y13: Inquiry Breakdown For Week
A14: Careers/Employment | E14: =sum(B14:D14) -> 0 | H14: 1 | I14: =sum(F14:H14) -> 1 | M14: =sum(J14:L14) -> 0 | Q14: =sum(N14:P14) -> 0 | U14: =sum(R14:T14) -> 0 | V14: =sum(E14,I14,M14,Q14,U14) -> 1 | W14: Referral | Z14: Monday | AA14: Tuesday | AB14: Wednesday | AC14: Thursday | AD14: Friday | AE14: Method
A15: CCS/Student Help Desk | E15: =sum(B15:D15) -> 0 | I15: =sum(F15:H15) -> 0 | M15: =sum(J15:L15) -> 0 | Q15: =sum(N15:P15) -> 0 | U15: =sum(R15:T15) -> 0 | V15: =sum(E15,I15,M15,Q15,U15) -> 0 | W15: Referral | Y15: Email | Z15: =B85 -> 28 | AA15: =F85 -> 11 | AB15: =J85 -> 10 | AC15: =N85 -> 7 | AD15: =R85 -> 3 | AE15: =sum(Z15:AD15) -> 59
A16: CEN100 | B16: 1 | E16: =sum(B16:D16) -> 1 | I16: =sum(F16:H16) -> 0 | M16: =sum(J16:L16) -> 0 | Q16: =sum(N16:P16) -> 0 | R16: 1 | U16: =sum(R16:T16) -> 1 | V16: =sum(E16,I16,M16,Q16,U16) -> 2 | W16: Academics | Y16: Phone | Z16: =C85 -> 0 | AA16: =G85 -> 0 | AB16: =K85 -> 0 | AC16: =O85 -> 0 | AD16: =S85 -> 0 | AE16: =sum(Z16:AD16) -> 0
A17: Chang School | B17: 1 | D17: 5 | E17: =sum(B17:D17) -> 6 | H17: 4 | I17: =sum(F17:H17) -> 4 | J17: 1 | L17: 4 | M17: =sum(J17:L17) -> 5 | N17: 1 | Q17: =sum(N17:P17) -> 1 | T17: 1 | U17: =sum(R17:T17) -> 1 | V17: =sum(E17,I17,M17,Q17,U17) -> 17 | W17: Referral | Y17: In-Person | Z17: =B86 -> 15 | AA17: =F86 -> 10 | AB17: =J86 -> 8 | AC17: =N86 -> 3 | AD17: =R86 -> 6 | AE17: =sum(Z17:AD17) -> 42
A18: Computer Labs | E18: =sum(B18:D18) -> 0 | I18: =sum(F18:H18) -> 0 | M18: =sum(J18:L18) -> 0 | Q18: =sum(N18:P18) -> 0 | U18: =sum(R18:T18) -> 0 | V18: =sum(E18,I18,M18,Q18,U18) -> 0 | W18: Referral | Y18: Inquiry Breakdown | Z18: =sum(Z15:Z17) -> 43 | AA18: =sum(AA15:AA17) -> 21 | AB18: =sum(AB15:AB17) -> 18 | AC18: =sum(AC15:AC17) -> 10 | AD18: =sum(AD15:AD17) -> 9 | AE18: =sum(Z18:AD18) -> 101
A19: Contact Info Requests | E19: =sum(B19:D19) -> 0 | I19: =sum(F19:H19) -> 0 | M19: =sum(J19:L19) -> 0 | Q19: =sum(N19:P19) -> 0 | U19: =sum(R19:T19) -> 0 | V19: =sum(E19,I19,M19,Q19,U19) -> 0 | W19: Referral
A20: Coop | E20: =sum(B20:D20) -> 0 | H20: 2 | I20: =sum(F20:H20) -> 2 | M20: =sum(J20:L20) -> 0 | Q20: =sum(N20:P20) -> 0 | U20: =sum(R20:T20) -> 0 | V20: =sum(E20,I20,M20,Q20,U20) -> 2 | W20: Referral
A21: Counselling Centre Appointments | B21: 1 | E21: =sum(B21:D21) -> 1 | I21: =sum(F21:H21) -> 0 | M21: =sum(J21:L21) -> 0 | Q21: =sum(N21:P21) -> 0 | U21: =sum(R21:T21) -> 0 | V21: =sum(E21,I21,M21,Q21,U21) -> 1 | W21: Mental Health and Wellness | Y21: Inquiry Timings - Monday
A22: Course Delivery | E22: =sum(B22:D22) -> 0 | I22: =sum(F22:H22) -> 0 | M22: =sum(J22:L22) -> 0 | P22: 1 | Q22: =sum(N22:P22) -> 1 | U22: =sum(R22:T22) -> 0 | V22: =sum(E22,I22,M22,Q22,U22) -> 1 | W22: Referral | Y22: Time | Z22: Number of People | AA22: Topic of inquiries | AB22: Phone | AC22: In-Person
A23: Course Drop | B23: 1 | E23: =sum(B23:D23) -> 1 | F23: 2 | I23: =sum(F23:H23) -> 2 | L23: 1 | M23: =sum(J23:L23) -> 1 | N23: 2 | Q23: =sum(N23:P23) -> 2 | T23: 1 | U23: =sum(R23:T23) -> 1 | V23: =sum(E23,I23,M23,Q23,U23) -> 7 | W23: Academics | Y23: 45179 | AB23: FALSE | AC23: FALSE
A24: Course Enrollment | D24: 4 | E24: =sum(B24:D24) -> 4 | F24: 1 | H24: 1 | I24: =sum(F24:H24) -> 2 | J24: 1 | L24: 8 | M24: =sum(J24:L24) -> 9 | N24: 1 | Q24: =sum(N24:P24) -> 1 | T24: 2 | U24: =sum(R24:T24) -> 2 | V24: =sum(E24,I24,M24,Q24,U24) -> 18 | W24: Academics | Y24: 45210 | AB24: FALSE | AC24: FALSE
A25: Course Intentions | E25: =sum(B25:D25) -> 0 | I25: =sum(F25:H25) -> 0 | M25: =sum(J25:L25) -> 0 | Q25: =sum(N25:P25) -> 0 | U25: =sum(R25:T25) -> 0 | V25: =sum(E25,I25,M25,Q25,U25) -> 0 | W25: Academics | Y25: 45242 | AB25: FALSE | AC25: FALSE
A26: Course Outlines | B26: 1 | E26: =sum(B26:D26) -> 1 | I26: =sum(F26:H26) -> 0 | M26: =sum(J26:L26) -> 0 | Q26: =sum(N26:P26) -> 0 | U26: =sum(R26:T26) -> 0 | V26: =sum(E26,I26,M26,Q26,U26) -> 1 | W26: Referral | Y26: 45261 | AB26: FALSE | AC26: FALSE
A27: Course Planning/Course Load management | E27: =sum(B27:D27) -> 0 | I27: =sum(F27:H27) -> 0 | M27: =sum(J27:L27) -> 0 | Q27: =sum(N27:P27) -> 0 | U27: =sum(R27:T27) -> 0 | V27: =sum(E27,I27,M27,Q27,U27) -> 0 | W27: Academics | Y27: 44928 | AB27: FALSE | AC27: FALSE
A28: Course Swap | E28: =sum(B28:D28) -> 0 | I28: =sum(F28:H28) -> 0 | M28: =sum(J28:L28) -> 0 | Q28: =sum(N28:P28) -> 0 | U28: =sum(R28:T28) -> 0 | V28: =sum(E28,I28,M28,Q28,U28) -> 0 | W28: Academics | Y28: 44960 | AB28: FALSE | AC28: FALSE
A29: D2L | B29: 2 | E29: =sum(B29:D29) -> 2 | I29: =sum(F29:H29) -> 0 | L29: 1 | M29: =sum(J29:L29) -> 1 | Q29: =sum(N29:P29) -> 0 | U29: =sum(R29:T29) -> 0 | V29: =sum(E29,I29,M29,Q29,U29) -> 3 | W29: Academics | Y29: 44989 | AB29: FALSE | AC29: FALSE
A30: Directions | E30: =sum(B30:D30) -> 0 | H30: 4 | I30: =sum(F30:H30) -> 4 | M30: =sum(J30:L30) -> 0 | P30: 1 | Q30: =sum(N30:P30) -> 1 | T30: 2 | U30: =sum(R30:T30) -> 2 | V30: =sum(E30,I30,M30,Q30,U30) -> 7 | W30: Other
A31: Discipline | E31: =sum(B31:D31) -> 0 | I31: =sum(F31:H31) -> 0 | M31: =sum(J31:L31) -> 0 | Q31: =sum(N31:P31) -> 0 | U31: =sum(R31:T31) -> 0 | V31: =sum(E31,I31,M31,Q31,U31) -> 0 | W31: Referral
A32: Early Intervention | E32: =sum(B32:D32) -> 0 | I32: =sum(F32:H32) -> 0 | M32: =sum(J32:L32) -> 0 | Q32: =sum(N32:P32) -> 0 | U32: =sum(R32:T32) -> 0 | V32: =sum(E32,I32,M32,Q32,U32) -> 0 | W32: Academics | Y32: Inquiry Timings - Tuesday
A33: Engineering Program Transition Courses | B33: 8 | D33: 1 | E33: =sum(B33:D33) -> 9 | F33: 2 | H33: 5 | I33: =sum(F33:H33) -> 7 | J33: 1 | L33: 3 | M33: =sum(J33:L33) -> 4 | P33: 1 | Q33: =sum(N33:P33) -> 1 | U33: =sum(R33:T33) -> 0 | V33: =sum(E33,I33,M33,Q33,U33) -> 21 | W33: Academics | Y33: Time | Z33: Number of People | AA33: Topic of inquiries | AB33: Phone | AC33: In-Person
A34: Enrollment Period | D34: 1 | E34: =sum(B34:D34) -> 1 | I34: =sum(F34:H34) -> 0 | M34: =sum(J34:L34) -> 0 | Q34: =sum(N34:P34) -> 0 | U34: =sum(R34:T34) -> 0 | V34: =sum(E34,I34,M34,Q34,U34) -> 1 | W34: Academics | Y34: 45179 | AB34: FALSE | AC34: FALSE
A35: Exams/Mid-Terms | E35: =sum(B35:D35) -> 0 | I35: =sum(F35:H35) -> 0 | M35: =sum(J35:L35) -> 0 | Q35: =sum(N35:P35) -> 0 | U35: =sum(R35:T35) -> 0 | V35: =sum(E35,I35,M35,Q35,U35) -> 0 | W35: Academics | Y35: 45210 | AB35: FALSE | AC35: FALSE
A36: Fees | B36: 1 | D36: 2 | E36: =sum(B36:D36) -> 3 | H36: 1 | I36: =sum(F36:H36) -> 1 | M36: =sum(J36:L36) -> 0 | Q36: =sum(N36:P36) -> 0 | U36: =sum(R36:T36) -> 0 | V36: =sum(E36,I36,M36,Q36,U36) -> 4 | W36: Financial | Y36: 45242 | AB36: FALSE | AC36: FALSE
A37: First Year Ambassador Program | E37: =sum(B37:D37) -> 0 | H37: 1 | I37: =sum(F37:H37) -> 1 | M37: =sum(J37:L37) -> 0 | Q37: =sum(N37:P37) -> 0 | U37: =sum(R37:T37) -> 0 | V37: =sum(E37,I37,M37,Q37,U37) -> 1 | W37: Academics | Y37: 45261 | AB37: FALSE | AC37: FALSE
A38: First Year in Two Years | E38: =sum(B38:D38) -> 0 | H38: 1 | I38: =sum(F38:H38) -> 1 | M38: =sum(J38:L38) -> 0 | Q38: =sum(N38:P38) -> 0 | U38: =sum(R38:T38) -> 0 | V38: =sum(E38,I38,M38,Q38,U38) -> 1 | W38: Academics | Y38: 44928 | AB38: FALSE | AC38: FALSE
A39: Fresh Start / Reinstatement | E39: =sum(B39:D39) -> 0 | I39: =sum(F39:H39) -> 0 | M39: =sum(J39:L39) -> 0 | Q39: =sum(N39:P39) -> 0 | U39: =sum(R39:T39) -> 0 | V39: =sum(E39,I39,M39,Q39,U39) -> 0 | W39: Academics | Y39: 44960 | AB39: FALSE | AC39: FALSE
A40: General Academic Advising | E40: =sum(B40:D40) -> 0 | I40: =sum(F40:H40) -> 0 | M40: =sum(J40:L40) -> 0 | Q40: =sum(N40:P40) -> 0 | U40: =sum(R40:T40) -> 0 | V40: =sum(E40,I40,M40,Q40,U40) -> 0 | W40: Academics | Y40: 44989 | AB40: FALSE | AC40: FALSE
A41: GPA/CGPA | E41: =sum(B41:D41) -> 0 | H41: 1 | I41: =sum(F41:H41) -> 1 | M41: =sum(J41:L41) -> 0 | Q41: =sum(N41:P41) -> 0 | U41: =sum(R41:T41) -> 0 | V41: =sum(E41,I41,M41,Q41,U41) -> 1 | W41: Academics
...

Sheet W3
B1: 45334 | F1: 45335 | J1: 45336 | N1: 45337 | R1: 45338
A3: Inquiry/Response | B3: Email | C3: Phone | D3: In-per | E3: D-Total | F3: Email | G3: Phone | H3: In-per | I3: D-Total | J3: Email | K3: Phone | L3: In-per | M3: D-Total | N3: Email | O3: Phone | P3: In-per | Q3: D-Total | R3: Email | S3: Phone | T3: In-per | U3: D-Total | V3: Prim-Catgry Tot | W3: Categories
A4: Academic Advising Appointments | E4: =sum(B4:D4) -> 0 | F4: 1 | I4: =sum(F4:H4) -> 1 | M4: =sum(J4:L4) -> 0 | P4: 1 | Q4: =sum(N4:P4) -> 1 | R4: 1 | T4: 2 | U4: =sum(R4:T4) -> 3 | V4: =sum(E4,I4,M4,Q4,U4) -> 5 | W4: Academics
A5: Academic Consideration Requests (ACRs) - Missing Classes | B5: 4 | D5: 1 | E5: =sum(B5:D5) -> 5 | F5: 2 | H5: 1 | I5: =sum(F5:H5) -> 3 | J5: 1 | L5: 2 | M5: =sum(J5:L5) -> 3 | Q5: =sum(N5:P5) -> 0 | R5: 4 | T5: 1 | U5: =sum(R5:T5) -> 5 | V5: =sum(E5,I5,M5,Q5,U5) -> 16 | W5: Academics | Y5: Main Catergories Analysis | Z5: #'s | AG5: Top 5 Categories
A6: Academic Standing | E6: =sum(B6:D6) -> 0 | I6: =sum(F6:H6) -> 0 | M6: =sum(J6:L6) -> 0 | Q6: =sum(N6:P6) -> 0 | U6: =sum(R6:T6) -> 0 | V6: =sum(E6,I6,M6,Q6,U6) -> 0 | W6: Academics | Y6: Academics | Z6: =SUMIF(W:W,"Academics",V:V) -> 50 | AH6: Inquiry | AI6: Amount
A7: Access Centre/Academic Accomodation Support | E7: =sum(B7:D7) -> 0 | I7: =sum(F7:H7) -> 0 | M7: =sum(J7:L7) -> 0 | Q7: =sum(N7:P7) -> 0 | U7: =sum(R7:T7) -> 0 | V7: =sum(E7,I7,M7,Q7,U7) -> 0 | W7: Academics | Y7: Referral | Z7: =SUMIF(W:W,"Referral",V:V) -> 13 | AG7: 1 | AH7: {=IFERROR(TEXTJOIN(", ", TRUE, IF($V$4:$V$84=AI7, $A$4:$A$84, "")), "")} -> Academic Consideration Requests (ACRs) - Missing Classes | AI7: =LARGE($V$4:$V$84,1) -> 16
A8: ACES | B8: 1 | E8: =sum(B8:D8) -> 1 | I8: =sum(F8:H8) -> 0 | M8: =sum(J8:L8) -> 0 | Q8: =sum(N8:P8) -> 0 | U8: =sum(R8:T8) -> 0 | V8: =sum(E8,I8,M8,Q8,U8) -> 1 | W8: Academics | Y8: Financial | Z8: =SUMIF(W:W,"Financial",V:V) -> 4 | AG8: 2 | AH8: {=IFERROR(TEXTJOIN(", ", TRUE, IF($V$4:$V$84=AI8, $A$4:$A$84, "")), "")} -> Course Enrollment | AI8: {=LARGE(IF($V$4:$V$84<>MAX($AI$7:AI7),$V$4:$V$84),1)} -> 7
A9: Admissions | D9: 1 | E9: =sum(B9:D9) -> 1 | F9: 1 | I9: =sum(F9:H9) -> 1 | L9: 1 | M9: =sum(J9:L9) -> 1 | Q9: =sum(N9:P9) -> 0 | U9: =sum(R9:T9) -> 0 | V9: =sum(E9,I9,M9,Q9,U9) -> 3 | W9: Referral | Y9: Mental Health and Wellness | Z9: =SUMIF(W:W, "Mental Health and Wellness", V:V) -> 0 | AG9: 3 | AH9: {=IFERROR(TEXTJOIN(", ", TRUE, IF($V$4:$V$84=AI9, $A$4:$A$84, "")), "")} -> Chang School | AI9: {=LARGE(IF($V$4:$V$84<>MAX($AI$7:AI7),IF($V$4:$V$84<>MAX($AI$8:AI8),$V$4:$V$84)),1)} -> 6
A10: Advisement Report | E10: =sum(B10:D10) -> 0 | I10: =sum(F10:H10) -> 0 | M10: =sum(J10:L10) -> 0 | Q10: =sum(N10:P10) -> 0 | U10: =sum(R10:T10) -> 0 | V10: =sum(E10,I10,M10,Q10,U10) -> 0 | W10: Academics | Y10: Other | Z10: =SUMIF(W:W, "Other", V:V) -> 13 | AG10: 4 | AH10: {=IFERROR(TEXTJOIN(", ", TRUE, IF($V$4:$V$84=AI10, $A$4:$A$84, "")), "")} -> Academic Advising Appointments, Directions, Supplies Request, e.g. stapler, scissor, etc | AI10: {=LARGE(IF($V$4:$V$84<>MAX($AI$7:AI7), IF($V$4:$V$84<>MAX($AI$8:AI8), IF($V$4:$V$84<>MAX($AI$9:AI9), $V$4:$V$84))), 1)} -> 5
A11: Appeals | E11: =sum(B11:D11) -> 0 | I11: =sum(F11:H11) -> 0 | M11: =sum(J11:L11) -> 0 | Q11: =sum(N11:P11) -> 0 | R11: 1 | U11: =sum(R11:T11) -> 1 | V11: =sum(E11,I11,M11,Q11,U11) -> 1 | W11: Referral | AG11: 5 | AH11: {=IFERROR(TEXTJOIN(", ", TRUE, IF($V$4:$V$84=AI11, $A$4:$A$84, "")), "")} -> Plan Change | AI11: {=LARGE(IF($V$4:$V$84<>MAX($AI$7:AI7), IF($V$4:$V$84<>MAX($AI$8:AI8), IF($V$4:$V$84<>MAX($AI$9:AI9), IF($V$4:$V$84<>MAX($AI$10:AI10), $V$4:$V$84)))), 1)} -> 4
A12: Awards/Scholarships | E12: =sum(B12:D12) -> 0 | I12: =sum(F12:H12) -> 0 | M12: =sum(J12:L12) -> 0 | Q12: =sum(N12:P12) -> 0 | U12: =sum(R12:T12) -> 0 | V12: =sum(E12,I12,M12,Q12,U12) -> 0 | W12: Referral
A13: Building and Campus access | E13: =sum(B13:D13) -> 0 | I13: =sum(F13:H13) -> 0 | M13: =sum(J13:L13) -> 0 | Q13: =sum(N13:P13) -> 0 | U13: =sum(R13:T13) -> 0 | V13: =sum(E13,I13,M13,Q13,U13) -> 0 | W13: Referral | Y13: Inquiry Breakdown For Week
A14: Careers/Employment | E14: =sum(B14:D14) -> 0 | I14: =sum(F14:H14) -> 0 | M14: =sum(J14:L14) -> 0 | Q14: =sum(N14:P14) -> 0 | U14: =sum(R14:T14) -> 0 | V14: =sum(E14,I14,M14,Q14,U14) -> 0 | W14: Referral | Z14: Monday | AA14: Tuesday | AB14: Wednesday | AC14: Thursday | AD14: Friday | AE14: Method
A15: CCS/Student Help Desk | D15: 1 | E15: =sum(B15:D15) -> 1 | I15: =sum(F15:H15) -> 0 | M15: =sum(J15:L15) -> 0 | Q15: =sum(N15:P15) -> 0 | U15: =sum(R15:T15) -> 0 | V15: =sum(E15,I15,M15,Q15,U15) -> 1 | W15: Referral | Y15: Email | Z15: =B85 -> 12 | AA15: =F85 -> 9 | AB15: =J85 -> 2 | AC15: =N85 -> 1 | AD15: =R85 -> 9 | AE15: =sum(Z15:AD15) -> 33
A16: CEN100 | E16: =sum(B16:D16) -> 0 | I16: =sum(F16:H16) -> 0 | M16: =sum(J16:L16) -> 0 | Q16: =sum(N16:P16) -> 0 | U16: =sum(R16:T16) -> 0 | V16: =sum(E16,I16,M16,Q16,U16) -> 0 | W16: Academics | Y16: Phone | Z16: =C85 -> 0 | AA16: =G85 -> 0 | AB16: =K85 -> 4 | AC16: =O85 -> 0 | AD16: =S85 -> 0 | AE16: =sum(Z16:AD16) -> 4
A17: Chang School | B17: 1 | E17: =sum(B17:D17) -> 1 | F17: 1 | H17: 1 | I17: =sum(F17:H17) -> 2 | M17: =sum(J17:L17) -> 0 | Q17: =sum(N17:P17) -> 0 | R17: 1 | T17: 2 | U17: =sum(R17:T17) -> 3 | V17: =sum(E17,I17,M17,Q17,U17) -> 6 | W17: Referral | Y17: In-Person | Z17: =B86 -> 6 | AA17: =F86 -> 11 | AB17: =J86 -> 7 | AC17: =N86 -> 4 | AD17: =R86 -> 5 | AE17: =sum(Z17:AD17) -> 33
A18: Computer Labs | E18: =sum(B18:D18) -> 0 | I18: =sum(F18:H18) -> 0 | M18: =sum(J18:L18) -> 0 | Q18: =sum(N18:P18) -> 0 | U18: =sum(R18:T18) -> 0 | V18: =sum(E18,I18,M18,Q18,U18) -> 0 | W18: Referral | Y18: Inquiry Breakdown | Z18: =sum(Z15:Z17) -> 18 | AA18: =sum(AA15:AA17) -> 20 | AB18: =sum(AB15:AB17) -> 13 | AC18: =sum(AC15:AC17) -> 5 | AD18: =sum(AD15:AD17) -> 14 | AE18: =sum(Z18:AD18) -> 70
A19: Contact Info Requests | E19: =sum(B19:D19) -> 0 | I19: =sum(F19:H19) -> 0 | M19: =sum(J19:L19) -> 0 | Q19: =sum(N19:P19) -> 0 | U19: =sum(R19:T19) -> 0 | V19: =sum(E19,I19,M19,Q19,U19) -> 0 | W19: Referral
A20: Coop | E20: =sum(B20:D20) -> 0 | I20: =sum(F20:H20) -> 0 | M20: =sum(J20:L20) -> 0 | Q20: =sum(N20:P20) -> 0 | U20: =sum(R20:T20) -> 0 | V20: =sum(E20,I20,M20,Q20,U20) -> 0 | W20: Referral
A21: Counselling Centre Appointments | E21: =sum(B21:D21) -> 0 | I21: =sum(F21:H21) -> 0 | M21: =sum(J21:L21) -> 0 | Q21: =sum(N21:P21) -> 0 | U21: =sum(R21:T21) -> 0 | V21: =sum(E21,I21,M21,Q21,U21) -> 0 | W21: Mental Health and Wellness | Y21: Inquiry Timings - Monday
A22: Course Delivery | E22: =sum(B22:D22) -> 0 | I22: =sum(F22:H22) -> 0 | M22: =sum(J22:L22) -> 0 | Q22: =sum(N22:P22) -> 0 | U22: =sum(R22:T22) -> 0 | V22: =sum(E22,I22,M22,Q22,U22) -> 0 | W22: Referral | Y22: Time | Z22: Number of People | AA22: Topic of inquiries | AB22: Phone | AC22: In-Person
A23: Course Drop | E23: =sum(B23:D23) -> 0 | I23: =sum(F23:H23) -> 0 | M23: =sum(J23:L23) -> 0 | P23: 1 | Q23: =sum(N23:P23) -> 1 | U23: =sum(R23:T23) -> 0 | V23: =sum(E23,I23,M23,Q23,U23) -> 1 | W23: Academics | Y23: 45179 | AB23: FALSE | AC23: FALSE
A24: Course Enrollment | D24: 2 | E24: =sum(B24:D24) -> 2 | F24: 1 | H24: 3 | I24: =sum(F24:H24) -> 4 | M24: =sum(J24:L24) -> 0 | P24: 1 | Q24: =sum(N24:P24) -> 1 | U24: =sum(R24:T24) -> 0 | V24: =sum(E24,I24,M24,Q24,U24) -> 7 | W24: Academics | Y24: 45210 | AB24: FALSE | AC24: FALSE
A25: Course Intentions | E25: =sum(B25:D25) -> 0 | I25: =sum(F25:H25) -> 0 | M25: =sum(J25:L25) -> 0 | Q25: =sum(N25:P25) -> 0 | U25: =sum(R25:T25) -> 0 | V25: =sum(E25,I25,M25,Q25,U25) -> 0 | W25: Academics | Y25: 45242 | AB25: FALSE | AC25: FALSE
A26: Course Outlines | E26: =sum(B26:D26) -> 0 | I26: =sum(F26:H26) -> 0 | M26: =sum(J26:L26) -> 0 | Q26: =sum(N26:P26) -> 0 | U26: =sum(R26:T26) -> 0 | V26: =sum(E26,I26,M26,Q26,U26) -> 0 | W26: Referral | Y26: 45261 | AB26: FALSE | AC26: FALSE
A27: Course Planning/Course Load management | E27: =sum(B27:D27) -> 0 | I27: =sum(F27:H27) -> 0 | M27: =sum(J27:L27) -> 0 | Q27: =sum(N27:P27) -> 0 | R27: 1 | U27: =sum(R27:T27) -> 1 | V27: =sum(E27,I27,M27,Q27,U27) -> 1 | W27: Academics | Y27: 44928 | AB27: FALSE | AC27: FALSE
A28: Course Swap | B28: 1 | E28: =sum(B28:D28) -> 1 | H28: 1 | I28: =sum(F28:H28) -> 1 | M28: =sum(J28:L28) -> 0 | Q28: =sum(N28:P28) -> 0 | U28: =sum(R28:T28) -> 0 | V28: =sum(E28,I28,M28,Q28,U28) -> 2 | W28: Academics | Y28: 44960 | AB28: FALSE | AC28: FALSE
A29: D2L | E29: =sum(B29:D29) -> 0 | I29: =sum(F29:H29) -> 0 | M29: =sum(J29:L29) -> 0 | Q29: =sum(N29:P29) -> 0 | U29: =sum(R29:T29) -> 0 | V29: =sum(E29,I29,M29,Q29,U29) -> 0 | W29: Academics | Y29: 44989 | AB29: FALSE | AC29: FALSE
A30: Directions | D30: 1 | E30: =sum(B30:D30) -> 1 | H30: 3 | I30: =sum(F30:H30) -> 3 | M30: =sum(J30:L30) -> 0 | Q30: =sum(N30:P30) -> 0 | R30: 1 | U30: =sum(R30:T30) -> 1 | V30: =sum(E30,I30,M30,Q30,U30) -> 5 | W30: Other
A31: Discipline | E31: =sum(B31:D31) -> 0 | I31: =sum(F31:H31) -> 0 | M31: =sum(J31:L31) -> 0 | Q31: =sum(N31:P31) -> 0 | U31: =sum(R31:T31) -> 0 | V31: =sum(E31,I31,M31,Q31,U31) -> 0 | W31: Referral
A32: Early Intervention | E32: =sum(B32:D32) -> 0 | I32: =sum(F32:H32) -> 0 | M32: =sum(J32:L32) -> 0 | Q32: =sum(N32:P32) -> 0 | U32: =sum(R32:T32) -> 0 | V32: =sum(E32,I32,M32,Q32,U32) -> 0 | W32: Academics | Y32: Inquiry Timings - Tuesday
A33: Engineering Program Transition Courses | B33: 1 | E33: =sum(B33:D33) -> 1 | H33: 2 | I33: =sum(F33:H33) -> 2 | M33: =sum(J33:L33) -> 0 | Q33: =sum(N33:P33) -> 0 | U33: =sum(R33:T33) -> 0 | V33: =sum(E33,I33,M33,Q33,U33) -> 3 | W33: Academics | Y33: Time | Z33: Number of People | AA33: Topic of inquiries | AB33: Phone | AC33: In-Person
A34: Enrollment Period | E34: =sum(B34:D34) -> 0 | I34: =sum(F34:H34) -> 0 | M34: =sum(J34:L34) -> 0 | Q34: =sum(N34:P34) -> 0 | U34: =sum(R34:T34) -> 0 | V34: =sum(E34,I34,M34,Q34,U34) -> 0 | W34: Academics | Y34: 45179 | AB34: FALSE | AC34: FALSE
A35: Exams/Mid-Terms | B35: 1 | E35: =sum(B35:D35) -> 1 | I35: =sum(F35:H35) -> 0 | L35: 1 | M35: =sum(J35:L35) -> 1 | Q35: =sum(N35:P35) -> 0 | U35: =sum(R35:T35) -> 0 | V35: =sum(E35,I35,M35,Q35,U35) -> 2 | W35: Academics | Y35: 45210 | AB35: FALSE | AC35: FALSE
A36: Fees | E36: =sum(B36:D36) -> 0 | F36: 1 | H36: 1 | I36: =sum(F36:H36) -> 2 | M36: =sum(J36:L36) -> 0 | N36: 1 | Q36: =sum(N36:P36) -> 1 | U36: =sum(R36:T36) -> 0 | V36: =sum(E36,I36,M36,Q36,U36) -> 3 | W36: Financial | Y36: 45242 | AB36: FALSE | AC36: FALSE
A37: First Year Ambassador Program | E37: =sum(B37:D37) -> 0 | I37: =sum(F37:H37) -> 0 | M37: =sum(J37:L37) -> 0 | Q37: =sum(N37:P37) -> 0 | U37: =sum(R37:T37) -> 0 | V37: =sum(E37,I37,M37,Q37,U37) -> 0 | W37: Academics | Y37: 45261 | AB37: FALSE | AC37: FALSE
A38: First Year in Two Years | D38: 1 | E38: =sum(B38:D38) -> 1 | I38: =sum(F38:H38) -> 0 | M38: =sum(J38:L38) -> 0 | Q38: =sum(N38:P38) -> 0 | U38: =sum(R38:T38) -> 0 | V38: =sum(E38,I38,M38,Q38,U38) -> 1 | W38: Academics | Y38: 44928 | AB38: FALSE | AC38: FALSE
A39: Fresh Start / Reinstatement | E39: =sum(B39:D39) -> 0 | I39: =sum(F39:H39) -> 0 | M39: =sum(J39:L39) -> 0 | Q39: =sum(N39:P39) -> 0 | U39: =sum(R39:T39) -> 0 | V39: =sum(E39,I39,M39,Q39,U39) -> 0 | W39: Academics | Y39: 44960 | AB39: FALSE | AC39: FALSE
A40: General Academic Advising | E40: =sum(B40:D40) -> 0 | I40: =sum(F40:H40) -> 0 | M40: =sum(J40:L40) -> 0 | Q40: =sum(N40:P40) -> 0 | U40: =sum(R40:T40) -> 0 | V40: =sum(E40,I40,M40,Q40,U40) -> 0 | W40: Academics | Y40: 44989 | AB40: FALSE | AC40: FALSE
A41: GPA/CGPA | D41: 1 | E41: =sum(B41:D41) -> 1 | I41: =sum(F41:H41) -> 0 | M41: =sum(J41:L41) -> 0 | Q41: =sum(N41:P41) -> 0 | U41: =sum(R41:T41) -> 0 | V41: =sum(E41,I41,M41,Q41,U41) -> 1 | W41: Academics
...

Sheet W4
B1: 45341 | F1: 45342 | J1: 45343 | N1: 45344 | R1: 45345
A3: Inquiry/Response | B3: Email | C3: Phone | D3: In-per | E3: D-Total | F3: Email | G3: Phone | H3: In-per | I3: D-Total | J3: Email | K3: Phone | L3: In-per | M3: D-Total | N3: Email | O3: Phone | P3: In-per | Q3: D-Total | R3: Email | S3: Phone | T3: In-per | U3: D-Total | V3: Prim-Catgry Tot | W3: Categories
A4: Academic Advising Appointments | B4: 1 | E4: =sum(B4:D4) -> 1 | I4: =sum(F4:H4) -> 0 | J4: 1 | M4: =sum(J4:L4) -> 1 | Q4: =sum(N4:P4) -> 0 | R4: 1 | U4: =sum(R4:T4) -> 1 | V4: =sum(E4,I4,M4,Q4,U4) -> 3 | W4: Academics
A5: Academic Consideration Requests (ACRs) - Missing Classes | B5: 1 | E5: =sum(B5:D5) -> 1 | F5: 1 | I5: =sum(F5:H5) -> 1 | M5: =sum(J5:L5) -> 0 | N5: 1 | P5: 1 | Q5: =sum(N5:P5) -> 2 | R5: 1 | U5: =sum(R5:T5) -> 1 | V5: =sum(E5,I5,M5,Q5,U5) -> 5 | W5: Academics | Y5: Main Catergories Analysis | Z5: #'s | AG5: Top 5 Categories
A6: Academic Standing | E6: =sum(B6:D6) -> 0 | I6: =sum(F6:H6) -> 0 | M6: =sum(J6:L6) -> 0 | Q6: =sum(N6:P6) -> 0 | U6: =sum(R6:T6) -> 0 | V6: =sum(E6,I6,M6,Q6,U6) -> 0 | W6: Academics | Y6: Academics | Z6: =SUMIF(W:W,"Academics",V:V) -> 22 | AH6: Inquiry | AI6: Amount
A7: Access Centre/Academic Accomodation Support | E7: =sum(B7:D7) -> 0 | I7: =sum(F7:H7) -> 0 | M7: =sum(J7:L7) -> 0 | Q7: =sum(N7:P7) -> 0 | U7: =sum(R7:T7) -> 0 | V7: =sum(E7,I7,M7,Q7,U7) -> 0 | W7: Academics | Y7: Referral | Z7: =SUMIF(W:W,"Referral",V:V) -> 6 | AG7: 1 | AH7: {=IFERROR(TEXTJOIN(", ", TRUE, IF($V$4:$V$84=AI7, $A$4:$A$84, "")), "")} -> Academic Consideration Requests (ACRs) - Missing Classes, Study Halls | AI7: =LARGE($V$4:$V$84,1) -> 5
A8: ACES | E8: =sum(B8:D8) -> 0 | I8: =sum(F8:H8) -> 0 | M8: =sum(J8:L8) -> 0 | Q8: =sum(N8:P8) -> 0 | U8: =sum(R8:T8) -> 0 | V8: =sum(E8,I8,M8,Q8,U8) -> 0 | W8: Academics | Y8: Financial | Z8: =SUMIF(W:W,"Financial",V:V) -> 3 | AG8: 2 | AH8: {=IFERROR(TEXTJOIN(", ", TRUE, IF($V$4:$V$84=AI8, $A$4:$A$84, "")), "")} -> Academic Advising Appointments, Admissions | AI8: {=LARGE(IF($V$4:$V$84<>MAX($AI$7:AI7),$V$4:$V$84),1)} -> 3
A9: Admissions | E9: =sum(B9:D9) -> 0 | I9: =sum(F9:H9) -> 0 | J9: 1 | M9: =sum(J9:L9) -> 1 | P9: 1 | Q9: =sum(N9:P9) -> 1 | T9: 1 | U9: =sum(R9:T9) -> 1 | V9: =sum(E9,I9,M9,Q9,U9) -> 3 | W9: Referral | Y9: Mental Health and Wellness | Z9: =SUMIF(W:W, "Mental Health and Wellness", V:V) -> 0 | AG9: 3 | AH9: {=IFERROR(TEXTJOIN(", ", TRUE, IF($V$4:$V$84=AI9, $A$4:$A$84, "")), "")} -> Course Drop, Course Outlines, Directions, Exams/Mid-Terms, Fees, Other | AI9: {=LARGE(IF($V$4:$V$84<>MAX($AI$7:AI7),IF($V$4:$V$84<>MAX($AI$8:AI8),$V$4:$V$84)),1)} -> 2
A10: Advisement Report | E10: =sum(B10:D10) -> 0 | I10: =sum(F10:H10) -> 0 | M10: =sum(J10:L10) -> 0 | Q10: =sum(N10:P10) -> 0 | U10: =sum(R10:T10) -> 0 | V10: =sum(E10,I10,M10,Q10,U10) -> 0 | W10: Academics | Y10: Other | Z10: =SUMIF(W:W, "Other", V:V) -> 3 | AG10: 4 | AH10: {=IFERROR(TEXTJOIN(", ", TRUE, IF($V$4:$V$84=AI10, $A$4:$A$84, "")), "")} -> CCS/Student Help Desk, Course Planning/Course Load management, Engineering Program Transition Courses, OSAP, Plan Change, Supplies Request, e.g. stapler, scissor, etc | AI10: {=LARGE(IF($V$4:$V$84<>MAX($AI$7:AI7), IF($V$4:$V$84<>MAX($AI$8:AI8), IF($V$4:$V$84<>MAX($AI$9:AI9), $V$4:$V$84))), 1)} -> 1
A11: Appeals | E11: =sum(B11:D11) -> 0 | I11: =sum(F11:H11) -> 0 | M11: =sum(J11:L11) -> 0 | Q11: =sum(N11:P11) -> 0 | U11: =sum(R11:T11) -> 0 | V11: =sum(E11,I11,M11,Q11,U11) -> 0 | W11: Referral | AG11: 5 | AH11: {=IFERROR(TEXTJOIN(", ", TRUE, IF($V$4:$V$84=AI11, $A$4:$A$84, "")), "")} -> Academic Standing, Access Centre/Academic Accomodation Support, ACES, Advisement Report, Appeals, Awards/Scholarships, Building and Campus access , Careers/Employment, CEN100, Chang School, Computer Labs, Contact Info Requests, Coop, Counselling Centre Appointments, Course Delivery , Course Enrollment , Course Intentions, Course Swap, D2L, Discipline , Early Intervention , Enrollment Period, First Year Ambassador Program, First Year in Two Years, Fresh Start / Reinstatement, General Academic Advising, GPA/CGPA, Graduate Studies, Holidays, e.g. Reading Week, Stat Holidays, etc, International Student Support, Letter of Permission/Taking Courses outside TMU, Liberals, Lockers, Lost and Found, Math Centre, Mentoring, Mini Math, Minors, MyServiceHub Navigation, One Card, Orientation, OSMS/OSEIE, Parents Night, Printing, Probation Contract, Probationary Standing, Promotion to 2nd Year, Proof of Enrollment/3rd Party Letter Request, Required to Withdraw (RTW), Residence/Student Housing, Retroactive Course Drop, Service Hub, Special Student (Not enrolled in Engineering at TMU), Student Clubs - General, Student Life and Learning Support (SLLS), Test Center/Makeup Exam, Toronto Mentropolitan Student Union (TMSU), Transfer Credits, Transferring Programs - Outside of Engineering, Tutoring - Student Learning Support, Upper Year Students, Wait List, Withdrawal - Permanent, Withdrawal - Short Term, Writing Test/CEN 199 | AI11: {=LARGE(IF($V$4:$V$84<>MAX($AI$7:AI7), IF($V$4:$V$84<>MAX($AI$8:AI8), IF($V$4:$V$84<>MAX($AI$9:AI9), IF($V$4:$V$84<>MAX($AI$10:AI10), $V$4:$V$84)))), 1)} -> 0
A12: Awards/Scholarships | E12: =sum(B12:D12) -> 0 | I12: =sum(F12:H12) -> 0 | M12: =sum(J12:L12) -> 0 | Q12: =sum(N12:P12) -> 0 | U12: =sum(R12:T12) -> 0 | V12: =sum(E12,I12,M12,Q12,U12) -> 0 | W12: Referral
A13: Building and Campus access | E13: =sum(B13:D13) -> 0 | I13: =sum(F13:H13) -> 0 | M13: =sum(J13:L13) -> 0 | Q13: =sum(N13:P13) -> 0 | U13: =sum(R13:T13) -> 0 | V13: =sum(E13,I13,M13,Q13,U13) -> 0 | W13: Referral | Y13: Inquiry Breakdown For Week
A14: Careers/Employment | E14: =sum(B14:D14) -> 0 | I14: =sum(F14:H14) -> 0 | M14: =sum(J14:L14) -> 0 | Q14: =sum(N14:P14) -> 0 | U14: =sum(R14:T14) -> 0 | V14: =sum(E14,I14,M14,Q14,U14) -> 0 | W14: Referral | Z14: Monday | AA14: Tuesday | AB14: Wednesday | AC14: Thursday | AD14: Friday | AE14: Method
A15: CCS/Student Help Desk | E15: =sum(B15:D15) -> 0 | F15: 1 | I15: =sum(F15:H15) -> 1 | M15: =sum(J15:L15) -> 0 | Q15: =sum(N15:P15) -> 0 | U15: =sum(R15:T15) -> 0 | V15: =sum(E15,I15,M15,Q15,U15) -> 1 | W15: Referral | Y15: Email | Z15: =B85 -> 4 | AA15: =F85 -> 4 | AB15: =J85 -> 5 | AC15: =N85 -> 5 | AD15: =R85 -> 7 | AE15: =sum(Z15:AD15) -> 25
A16: CEN100 | E16: =sum(B16:D16) -> 0 | I16: =sum(F16:H16) -> 0 | M16: =sum(J16:L16) -> 0 | Q16: =sum(N16:P16) -> 0 | U16: =sum(R16:T16) -> 0 | V16: =sum(E16,I16,M16,Q16,U16) -> 0 | W16: Academics | Y16: Phone | Z16: =C85 -> 0 | AA16: =G85 -> 0 | AB16: =K85 -> 0 | AC16: =O85 -> 0 | AD16: =S85 -> 0 | AE16: =sum(Z16:AD16) -> 0
A17: Chang School | E17: =sum(B17:D17) -> 0 | I17: =sum(F17:H17) -> 0 | M17: =sum(J17:L17) -> 0 | Q17: =sum(N17:P17) -> 0 | U17: =sum(R17:T17) -> 0 | V17: =sum(E17,I17,M17,Q17,U17) -> 0 | W17: Referral | Y17: In-Person | Z17: =B86 -> 0 | AA17: =F86 -> 0 | AB17: =J86 -> 0 | AC17: =N86 -> 5 | AD17: =R86 -> 2 | AE17: =sum(Z17:AD17) -> 7
A18: Computer Labs | E18: =sum(B18:D18) -> 0 | I18: =sum(F18:H18) -> 0 | M18: =sum(J18:L18) -> 0 | Q18: =sum(N18:P18) -> 0 | U18: =sum(R18:T18) -> 0 | V18: =sum(E18,I18,M18,Q18,U18) -> 0 | W18: Referral | Y18: Inquiry Breakdown | Z18: =sum(Z15:Z17) -> 4 | AA18: =sum(AA15:AA17) -> 4 | AB18: =sum(AB15:AB17) -> 5 | AC18: =sum(AC15:AC17) -> 10 | AD18: =sum(AD15:AD17) -> 9 | AE18: =sum(Z18:AD18) -> 32
A19: Contact Info Requests | E19: =sum(B19:D19) -> 0 | I19: =sum(F19:H19) -> 0 | M19: =sum(J19:L19) -> 0 | Q19: =sum(N19:P19) -> 0 | U19: =sum(R19:T19) -> 0 | V19: =sum(E19,I19,M19,Q19,U19) -> 0 | W19: Referral
A20: Coop | E20: =sum(B20:D20) -> 0 | I20: =sum(F20:H20) -> 0 | M20: =sum(J20:L20) -> 0 | Q20: =sum(N20:P20) -> 0 | U20: =sum(R20:T20) -> 0 | V20: =sum(E20,I20,M20,Q20,U20) -> 0 | W20: Referral
A21: Counselling Centre Appointments | E21: =sum(B21:D21) -> 0 | I21: =sum(F21:H21) -> 0 | M21: =sum(J21:L21) -> 0 | Q21: =sum(N21:P21) -> 0 | U21: =sum(R21:T21) -> 0 | V21: =sum(E21,I21,M21,Q21,U21) -> 0 | W21: Mental Health and Wellness | Y21: Inquiry Timings - Monday
A22: Course Delivery | E22: =sum(B22:D22) -> 0 | I22: =sum(F22:H22) -> 0 | M22: =sum(J22:L22) -> 0 | Q22: =sum(N22:P22) -> 0 | U22: =sum(R22:T22) -> 0 | V22: =sum(E22,I22,M22,Q22,U22) -> 0 | W22: Referral | Y22: Time | Z22: Number of People | AA22: Topic of inquiries | AB22: Phone | AC22: In-Person
A23: Course Drop | E23: =sum(B23:D23) -> 0 | I23: =sum(F23:H23) -> 0 | M23: =sum(J23:L23) -> 0 | N23: 1 | P23: 1 | Q23: =sum(N23:P23) -> 2 | U23: =sum(R23:T23) -> 0 | V23: =sum(E23,I23,M23,Q23,U23) -> 2 | W23: Academics | Y23: 45179 | AB23: FALSE | AC23: FALSE
A24: Course Enrollment | E24: =sum(B24:D24) -> 0 | I24: =sum(F24:H24) -> 0 | M24: =sum(J24:L24) -> 0 | Q24: =sum(N24:P24) -> 0 | U24: =sum(R24:T24) -> 0 | V24: =sum(E24,I24,M24,Q24,U24) -> 0 | W24: Academics | Y24: 45210 | AB24: FALSE | AC24: FALSE
A25: Course Intentions | E25: =sum(B25:D25) -> 0 | I25: =sum(F25:H25) -> 0 | M25: =sum(J25:L25) -> 0 | Q25: =sum(N25:P25) -> 0 | U25: =sum(R25:T25) -> 0 | V25: =sum(E25,I25,M25,Q25,U25) -> 0 | W25: Academics | Y25: 45242 | AB25: FALSE | AC25: FALSE
A26: Course Outlines | E26: =sum(B26:D26) -> 0 | I26: =sum(F26:H26) -> 0 | J26: 2 | M26: =sum(J26:L26) -> 2 | Q26: =sum(N26:P26) -> 0 | U26: =sum(R26:T26) -> 0 | V26: =sum(E26,I26,M26,Q26,U26) -> 2 | W26: Referral | Y26: 45261 | AB26: FALSE | AC26: FALSE
A27: Course Planning/Course Load management | E27: =sum(B27:D27) -> 0 | I27: =sum(F27:H27) -> 0 | M27: =sum(J27:L27) -> 0 | P27: 1 | Q27: =sum(N27:P27) -> 1 | U27: =sum(R27:T27) -> 0 | V27: =sum(E27,I27,M27,Q27,U27) -> 1 | W27: Academics | Y27: 44928 | AB27: FALSE | AC27: FALSE
A28: Course Swap | E28: =sum(B28:D28) -> 0 | I28: =sum(F28:H28) -> 0 | M28: =sum(J28:L28) -> 0 | Q28: =sum(N28:P28) -> 0 | U28: =sum(R28:T28) -> 0 | V28: =sum(E28,I28,M28,Q28,U28) -> 0 | W28: Academics | Y28: 44960 | AB28: FALSE | AC28: FALSE
A29: D2L | E29: =sum(B29:D29) -> 0 | I29: =sum(F29:H29) -> 0 | M29: =sum(J29:L29) -> 0 | Q29: =sum(N29:P29) -> 0 | U29: =sum(R29:T29) -> 0 | V29: =sum(E29,I29,M29,Q29,U29) -> 0 | W29: Academics | Y29: 44989 | AB29: FALSE | AC29: FALSE
A30: Directions | E30: =sum(B30:D30) -> 0 | I30: =sum(F30:H30) -> 0 | M30: =sum(J30:L30) -> 0 | P30: 1 | Q30: =sum(N30:P30) -> 1 | T30: 1 | U30: =sum(R30:T30) -> 1 | V30: =sum(E30,I30,M30,Q30,U30) -> 2 | W30: Other
A31: Discipline | E31: =sum(B31:D31) -> 0 | I31: =sum(F31:H31) -> 0 | M31: =sum(J31:L31) -> 0 | Q31: =sum(N31:P31) -> 0 | U31: =sum(R31:T31) -> 0 | V31: =sum(E31,I31,M31,Q31,U31) -> 0 | W31: Referral
A32: Early Intervention | E32: =sum(B32:D32) -> 0 | I32: =sum(F32:H32) -> 0 | M32: =sum(J32:L32) -> 0 | Q32: =sum(N32:P32) -> 0 | U32: =sum(R32:T32) -> 0 | V32: =sum(E32,I32,M32,Q32,U32) -> 0 | W32: Academics | Y32: Inquiry Timings - Tuesday
A33: Engineering Program Transition Courses | E33: =sum(B33:D33) -> 0 | I33: =sum(F33:H33) -> 0 | M33: =sum(J33:L33) -> 0 | N33: 1 | Q33: =sum(N33:P33) -> 1 | U33: =sum(R33:T33) -> 0 | V33: =sum(E33,I33,M33,Q33,U33) -> 1 | W33: Academics | Y33: Time | Z33: Number of People | AA33: Topic of inquiries | AB33: Phone | AC33: In-Person
A34: Enrollment Period | E34: =sum(B34:D34) -> 0 | I34: =sum(F34:H34) -> 0 | M34: =sum(J34:L34) -> 0 | Q34: =sum(N34:P34) -> 0 | U34: =sum(R34:T34) -> 0 | V34: =sum(E34,I34,M34,Q34,U34) -> 0 | W34: Academics | Y34: 45179 | AB34: FALSE | AC34: FALSE
A35: Exams/Mid-Terms | E35: =sum(B35:D35) -> 0 | I35: =sum(F35:H35) -> 0 | M35: =sum(J35:L35) -> 0 | P35: 1 | Q35: =sum(N35:P35) -> 1 | R35: 1 | U35: =sum(R35:T35) -> 1 | V35: =sum(E35,I35,M35,Q35,U35) -> 2 | W35: Academics | Y35: 45210 | AB35: FALSE | AC35: FALSE
A36: Fees | B36: 1 | E36: =sum(B36:D36) -> 1 | I36: =sum(F36:H36) -> 0 | J36: 1 | M36: =sum(J36:L36) -> 1 | Q36: =sum(N36:P36) -> 0 | U36: =sum(R36:T36) -> 0 | V36: =sum(E36,I36,M36,Q36,U36) -> 2 | W36: Financial | Y36: 45242 | AB36: FALSE | AC36: FALSE
A37: First Year Ambassador Program | E37: =sum(B37:D37) -> 0 | I37: =sum(F37:H37) -> 0 | M37: =sum(J37:L37) -> 0 | Q37: =sum(N37:P37) -> 0 | U37: =sum(R37:T37) -> 0 | V37: =sum(E37,I37,M37,Q37,U37) -> 0 | W37: Academics | Y37: 45261 | AB37: FALSE | AC37: FALSE
A38: First Year in Two Years | E38: =sum(B38:D38) -> 0 | I38: =sum(F38:H38) -> 0 | M38: =sum(J38:L38) -> 0 | Q38: =sum(N38:P38) -> 0 | U38: =sum(R38:T38) -> 0 | V38: =sum(E38,I38,M38,Q38,U38) -> 0 | W38: Academics | Y38: 44928 | AB38: FALSE | AC38: FALSE
A39: Fresh Start / Reinstatement | E39: =sum(B39:D39) -> 0 | I39: =sum(F39:H39) -> 0 | M39: =sum(J39:L39) -> 0 | Q39: =sum(N39:P39) -> 0 | U39: =sum(R39:T39) -> 0 | V39: =sum(E39,I39,M39,Q39,U39) -> 0 | W39: Academics | Y39: 44960 | AB39: FALSE | AC39: FALSE
A40: General Academic Advising | E40: =sum(B40:D40) -> 0 | I40: =sum(F40:H40) -> 0 | M40: =sum(J40:L40) -> 0 | Q40: =sum(N40:P40) -> 0 | U40: =sum(R40:T40) -> 0 | V40: =sum(E40,I40,M40,Q40,U40) -> 0 | W40: Academics | Y40: 44989 | AB40: FALSE | AC40: FALSE
A41: GPA/CGPA | E41: =sum(B41:D41) -> 0 | I41: =sum(F41:H41) -> 0 | M41: =sum(J41:L41) -> 0 | Q41: =sum(N41:P41) -> 0 | U41: =sum(R41:T41) -> 0 | V41: =sum(E41,I41,M41,Q41,U41) -> 0 | W41: Academics
...

Sheet W5
B1: 45348 | F1: 45349 | J1: 45350 | N1: 45351
A3: Inquiry/Response | B3: Email | C3: Phone | D3: In-per | E3: D-Total | F3: Email | G3: Phone | H3: In-per | I3: D-Total | J3: Email | K3: Phone | L3: In-per | M3: D-Total | N3: Email | O3: Phone | P3: In-per | Q3: D-Total | R3: Email | S3: Phone | T3: In-per | U3: D-Total | V3: Prim-Catgry Tot | W3: Categories
A4: Academic Advising Appointments | B4: 1 | D4: 1 | E4: =sum(B4:D4) -> 2 | F4: 1 | H4: 1 | I4: =sum(F4:H4) -> 2 | M4: =sum(J4:L4) -> 0 | P4: 5 | Q4: =sum(N4:P4) -> 5 | U4: =sum(R4:T4) -> 0 | V4: =sum(E4,I4,M4,Q4,U4) -> 9 | W4: Academics
A5: Academic Consideration Requests (ACRs) - Missing Classes | D5: 2 | E5: =sum(B5:D5) -> 2 | F5: 2 | H5: 4 | I5: =sum(F5:H5) -> 6 | J5: 3 | L5: 2 | M5: =sum(J5:L5) -> 5 | N5: 1 | P5: 2 | Q5: =sum(N5:P5) -> 3 | U5: =sum(R5:T5) -> 0 | V5: =sum(E5,I5,M5,Q5,U5) -> 16 | W5: Academics | Y5: Main Catergories Analysis | Z5: #'s | AG5: Top 5 Categories
A6: Academic Standing | E6: =sum(B6:D6) -> 0 | I6: =sum(F6:H6) -> 0 | M6: =sum(J6:L6) -> 0 | Q6: =sum(N6:P6) -> 0 | U6: =sum(R6:T6) -> 0 | V6: =sum(E6,I6,M6,Q6,U6) -> 0 | W6: Academics | Y6: Academics | Z6: =SUMIF(W:W,"Academics",V:V) -> 93 | AH6: Inquiry | AI6: Amount
A7: Access Centre/Academic Accomodation Support | D7: 1 | E7: =sum(B7:D7) -> 1 | H7: 1 | I7: =sum(F7:H7) -> 1 | L7: 1 | M7: =sum(J7:L7) -> 1 | N7: 1 | Q7: =sum(N7:P7) -> 1 | U7: =sum(R7:T7) -> 0 | V7: =sum(E7,I7,M7,Q7,U7) -> 4 | W7: Academics | Y7: Referral | Z7: =SUMIF(W:W,"Referral",V:V) -> 27 | AG7: 1 | AH7: {=IFERROR(TEXTJOIN(", ", TRUE, IF($V$4:$V$84=AI7, $A$4:$A$84, "")), "")} -> Academic Consideration Requests (ACRs) - Missing Classes | AI7: =LARGE($V$4:$V$84,1) -> 16
A8: ACES | D8: 1 | E8: =sum(B8:D8) -> 1 | I8: =sum(F8:H8) -> 0 | M8: =sum(J8:L8) -> 0 | Q8: =sum(N8:P8) -> 0 | U8: =sum(R8:T8) -> 0 | V8: =sum(E8,I8,M8,Q8,U8) -> 1 | W8: Academics | Y8: Financial | Z8: =SUMIF(W:W,"Financial",V:V) -> 3 | AG8: 2 | AH8: {=IFERROR(TEXTJOIN(", ", TRUE, IF($V$4:$V$84=AI8, $A$4:$A$84, "")), "")} -> Course Drop | AI8: {=LARGE(IF($V$4:$V$84<>MAX($AI$7:AI7),$V$4:$V$84),1)} -> 13
A9: Admissions | D9: 1 | E9: =sum(B9:D9) -> 1 | I9: =sum(F9:H9) -> 0 | M9: =sum(J9:L9) -> 0 | Q9: =sum(N9:P9) -> 0 | U9: =sum(R9:T9) -> 0 | V9: =sum(E9,I9,M9,Q9,U9) -> 1 | W9: Referral | Y9: Mental Health and Wellness | Z9: =SUMIF(W:W, "Mental Health and Wellness", V:V) -> 1 | AG9: 3 | AH9: {=IFERROR(TEXTJOIN(", ", TRUE, IF($V$4:$V$84=AI9, $A$4:$A$84, "")), "")} -> Chang School | AI9: {=LARGE(IF($V$4:$V$84<>MAX($AI$7:AI7),IF($V$4:$V$84<>MAX($AI$8:AI8),$V$4:$V$84)),1)} -> 10
A10: Advisement Report | E10: =sum(B10:D10) -> 0 | I10: =sum(F10:H10) -> 0 | M10: =sum(J10:L10) -> 0 | Q10: =sum(N10:P10) -> 0 | U10: =sum(R10:T10) -> 0 | V10: =sum(E10,I10,M10,Q10,U10) -> 0 | W10: Academics | Y10: Other | Z10: =SUMIF(W:W, "Other", V:V) -> 8 | AG10: 4 | AH10: {=IFERROR(TEXTJOIN(", ", TRUE, IF($V$4:$V$84=AI10, $A$4:$A$84, "")), "")} -> Academic Advising Appointments, Engineering Program Transition Courses | AI10: {=LARGE(IF($V$4:$V$84<>MAX($AI$7:AI7), IF($V$4:$V$84<>MAX($AI$8:AI8), IF($V$4:$V$84<>MAX($AI$9:AI9), $V$4:$V$84))), 1)} -> 9
A11: Appeals | B11: 1 | E11: =sum(B11:D11) -> 1 | F11: 1 | I11: =sum(F11:H11) -> 1 | M11: =sum(J11:L11) -> 0 | N11: 1 | Q11: =sum(N11:P11) -> 1 | U11: =sum(R11:T11) -> 0 | V11: =sum(E11,I11,M11,Q11,U11) -> 3 | W11: Referral | AG11: 5 | AH11: {=IFERROR(TEXTJOIN(", ", TRUE, IF($V$4:$V$84=AI11, $A$4:$A$84, "")), "")} -> Course Enrollment , Exams/Mid-Terms | AI11: {=LARGE(IF($V$4:$V$84<>MAX($AI$7:AI7), IF($V$4:$V$84<>MAX($AI$8:AI8), IF($V$4:$V$84<>MAX($AI$9:AI9), IF($V$4:$V$84<>MAX($AI$10:AI10), $V$4:$V$84)))), 1)} -> 7
A12: Awards/Scholarships | E12: =sum(B12:D12) -> 0 | F12: 1 | I12: =sum(F12:H12) -> 1 | M12: =sum(J12:L12) -> 0 | Q12: =sum(N12:P12) -> 0 | U12: =sum(R12:T12) -> 0 | V12: =sum(E12,I12,M12,Q12,U12) -> 1 | W12: Referral
A13: Building and Campus access | E13: =sum(B13:D13) -> 0 | I13: =sum(F13:H13) -> 0 | M13: =sum(J13:L13) -> 0 | Q13: =sum(N13:P13) -> 0 | U13: =sum(R13:T13) -> 0 | V13: =sum(E13,I13,M13,Q13,U13) -> 0 | W13: Referral | Y13: Inquiry Breakdown For Week
A14: Careers/Employment | E14: =sum(B14:D14) -> 0 | H14: 1 | I14: =sum(F14:H14) -> 1 | M14: =sum(J14:L14) -> 0 | Q14: =sum(N14:P14) -> 0 | U14: =sum(R14:T14) -> 0 | V14: =sum(E14,I14,M14,Q14,U14) -> 1 | W14: Referral | Z14: Monday | AA14: Tuesday | AB14: Wednesday | AC14: Thursday | AD14: Friday | AE14: Method
A15: CCS/Student Help Desk | D15: 1 | E15: =sum(B15:D15) -> 1 | I15: =sum(F15:H15) -> 0 | M15: =sum(J15:L15) -> 0 | Q15: =sum(N15:P15) -> 0 | U15: =sum(R15:T15) -> 0 | V15: =sum(E15,I15,M15,Q15,U15) -> 1 | W15: Referral | Y15: Email | Z15: =B85 -> 8 | AA15: =F85 -> 15 | AB15: =J85 -> 17 | AC15: =N85 -> 13 | AD15: =R85 -> 0 | AE15: =sum(Z15:AD15) -> 53
A16: CEN100 | E16: =sum(B16:D16) -> 0 | I16: =sum(F16:H16) -> 0 | M16: =sum(J16:L16) -> 0 | Q16: =sum(N16:P16) -> 0 | U16: =sum(R16:T16) -> 0 | V16: =sum(E16,I16,M16,Q16,U16) -> 0 | W16: Academics | Y16: Phone | Z16: =C85 -> 0 | AA16: =G85 -> 0 | AB16: =K85 -> 0 | AC16: =O85 -> 0 | AD16: =S85 -> 0 | AE16: =sum(Z16:AD16) -> 0
A17: Chang School | D17: 1 | E17: =sum(B17:D17) -> 1 | F17: 1 | H17: 3 | I17: =sum(F17:H17) -> 4 | J17: 1 | L17: 1 | M17: =sum(J17:L17) -> 2 | N17: 2 | P17: 1 | Q17: =sum(N17:P17) -> 3 | U17: =sum(R17:T17) -> 0 | V17: =sum(E17,I17,M17,Q17,U17) -> 10 | W17: Referral | Y17: In-Person | Z17: =B86 -> 22 | AA17: =F86 -> 23 | AB17: =J86 -> 15 | AC17: =N86 -> 12 | AD17: =R86 | AE17: =sum(Z17:AD17) -> 72
A18: Computer Labs | E18: =sum(B18:D18) -> 0 | I18: =sum(F18:H18) -> 0 | M18: =sum(J18:L18) -> 0 | Q18: =sum(N18:P18) -> 0 | U18: =sum(R18:T18) -> 0 | V18: =sum(E18,I18,M18,Q18,U18) -> 0 | W18: Referral | Y18: Inquiry Breakdown | Z18: =sum(Z15:Z17) -> 30 | AA18: =sum(AA15:AA17) -> 38 | AB18: =sum(AB15:AB17) -> 32 | AC18: =sum(AC15:AC17) -> 25 | AD18: =sum(AD15:AD17) -> 0 | AE18: =sum(Z18:AD18) -> 125
A19: Contact Info Requests | E19: =sum(B19:D19) -> 0 | H19: 1 | I19: =sum(F19:H19) -> 1 | M19: =sum(J19:L19) -> 0 | Q19: =sum(N19:P19) -> 0 | U19: =sum(R19:T19) -> 0 | V19: =sum(E19,I19,M19,Q19,U19) -> 1 | W19: Referral
A20: Coop | E20: =sum(B20:D20) -> 0 | H20: 3 | I20: =sum(F20:H20) -> 3 | M20: =sum(J20:L20) -> 0 | Q20: =sum(N20:P20) -> 0 | U20: =sum(R20:T20) -> 0 | V20: =sum(E20,I20,M20,Q20,U20) -> 3 | W20: Referral
A21: Counselling Centre Appointments | E21: =sum(B21:D21) -> 0 | I21: =sum(F21:H21) -> 0 | M21: =sum(J21:L21) -> 0 | Q21: =sum(N21:P21) -> 0 | U21: =sum(R21:T21) -> 0 | V21: =sum(E21,I21,M21,Q21,U21) -> 0 | W21: Mental Health and Wellness | Y21: Inquiry Timings - Monday
A22: Course Delivery | E22: =sum(B22:D22) -> 0 | I22: =sum(F22:H22) -> 0 | M22: =sum(J22:L22) -> 0 | Q22: =sum(N22:P22) -> 0 | U22: =sum(R22:T22) -> 0 | V22: =sum(E22,I22,M22,Q22,U22) -> 0 | W22: Referral | Y22: Time | Z22: Number of People | AA22: Topic of inquiries | AB22: Phone | AC22: In-Person
A23: Course Drop | B23: 1 | D23: 2 | E23: =sum(B23:D23) -> 3 | F23: 1 | H23: 3 | I23: =sum(F23:H23) -> 4 | J23: 1 | L23: 3 | M23: =sum(J23:L23) -> 4 | N23: 2 | Q23: =sum(N23:P23) -> 2 | U23: =sum(R23:T23) -> 0 | V23: =sum(E23,I23,M23,Q23,U23) -> 13 | W23: Academics | Y23: 45179 | AB23: FALSE | AC23: FALSE
A24: Course Enrollment | D24: 3 | E24: =sum(B24:D24) -> 3 | H24: 1 | I24: =sum(F24:H24) -> 1 | J24: 1 | L24: 2 | M24: =sum(J24:L24) -> 3 | Q24: =sum(N24:P24) -> 0 | U24: =sum(R24:T24) -> 0 | V24: =sum(E24,I24,M24,Q24,U24) -> 7 | W24: Academics | Y24: 45210 | AB24: FALSE | AC24: FALSE
A25: Course Intentions | E25: =sum(B25:D25) -> 0 | I25: =sum(F25:H25) -> 0 | M25: =sum(J25:L25) -> 0 | Q25: =sum(N25:P25) -> 0 | U25: =sum(R25:T25) -> 0 | V25: =sum(E25,I25,M25,Q25,U25) -> 0 | W25: Academics | Y25: 45242 | AB25: FALSE | AC25: FALSE
A26: Course Outlines | E26: =sum(B26:D26) -> 0 | F26: 1 | I26: =sum(F26:H26) -> 1 | M26: =sum(J26:L26) -> 0 | Q26: =sum(N26:P26) -> 0 | U26: =sum(R26:T26) -> 0 | V26: =sum(E26,I26,M26,Q26,U26) -> 1 | W26: Referral | Y26: 45261 | AB26: FALSE | AC26: FALSE
A27: Course Planning/Course Load management | E27: =sum(B27:D27) -> 0 | I27: =sum(F27:H27) -> 0 | M27: =sum(J27:L27) -> 0 | Q27: =sum(N27:P27) -> 0 | U27: =sum(R27:T27) -> 0 | V27: =sum(E27,I27,M27,Q27,U27) -> 0 | W27: Academics | Y27: 44928 | AB27: FALSE | AC27: FALSE
A28: Course Swap | B28: 1 | E28: =sum(B28:D28) -> 1 | I28: =sum(F28:H28) -> 0 | M28: =sum(J28:L28) -> 0 | Q28: =sum(N28:P28) -> 0 | U28: =sum(R28:T28) -> 0 | V28: =sum(E28,I28,M28,Q28,U28) -> 1 | W28: Academics | Y28: 44960 | AB28: FALSE | AC28: FALSE
A29: D2L | E29: =sum(B29:D29) -> 0 | I29: =sum(F29:H29) -> 0 | M29: =sum(J29:L29) -> 0 | Q29: =sum(N29:P29) -> 0 | U29: =sum(R29:T29) -> 0 | V29: =sum(E29,I29,M29,Q29,U29) -> 0 | W29: Academics | Y29: 44989 | AB29: FALSE | AC29: FALSE
A30: Directions | D30: 1 | E30: =sum(B30:D30) -> 1 | H30: 1 | I30: =sum(F30:H30) -> 1 | L30: 2 | M30: =sum(J30:L30) -> 2 | Q30: =sum(N30:P30) -> 0 | U30: =sum(R30:T30) -> 0 | V30: =sum(E30,I30,M30,Q30,U30) -> 4 | W30: Other
A31: Discipline | E31: =sum(B31:D31) -> 0 | F31: 1 | I31: =sum(F31:H31) -> 1 | M31: =sum(J31:L31) -> 0 | Q31: =sum(N31:P31) -> 0 | U31: =sum(R31:T31) -> 0 | V31: =sum(E31,I31,M31,Q31,U31) -> 1 | W31: Referral
A32: Early Intervention | E32: =sum(B32:D32) -> 0 | I32: =sum(F32:H32) -> 0 | M32: =sum(J32:L32) -> 0 | Q32: =sum(N32:P32) -> 0 | U32: =sum(R32:T32) -> 0 | V32: =sum(E32,I32,M32,Q32,U32) -> 0 | W32: Academics | Y32: Inquiry Timings - Tuesday
A33: Engineering Program Transition Courses | D33: 1 | E33: =sum(B33:D33) -> 1 | F33: 1 | H33: 3 | I33: =sum(F33:H33) -> 4 | J33: 4 | M33: =sum(J33:L33) -> 4 | Q33: =sum(N33:P33) -> 0 | U33: =sum(R33:T33) -> 0 | V33: =sum(E33,I33,M33,Q33,U33) -> 9 | W33: Academics | Y33: Time | Z33: Number of People | AA33: Topic of inquiries | AB33: Phone | AC33: In-Person
A34: Enrollment Period | E34: =sum(B34:D34) -> 0 | I34: =sum(F34:H34) -> 0 | J34: 2 | M34: =sum(J34:L34) -> 2 | Q34: =sum(N34:P34) -> 0 | U34: =sum(R34:T34) -> 0 | V34: =sum(E34,I34,M34,Q34,U34) -> 2 | W34: Academics | Y34: 45179 | AB34: FALSE | AC34: FALSE
A35: Exams/Mid-Terms | B35: 1 | E35: =sum(B35:D35) -> 1 | F35: 1 | I35: =sum(F35:H35) -> 1 | L35: 3 | M35: =sum(J35:L35) -> 3 | N35: 2 | Q35: =sum(N35:P35) -> 2 | U35: =sum(R35:T35) -> 0 | V35: =sum(E35,I35,M35,Q35,U35) -> 7 | W35: Academics | Y35: 45210 | AB35: FALSE | AC35: FALSE
A36: Fees | D36: 1 | E36: =sum(B36:D36) -> 1 | I36: =sum(F36:H36) -> 0 | M36: =sum(J36:L36) -> 0 | N36: 1 | Q36: =sum(N36:P36) -> 1 | U36: =sum(R36:T36) -> 0 | V36: =sum(E36,I36,M36,Q36,U36) -> 2 | W36: Financial | Y36: 45242 | AB36: FALSE | AC36: FALSE
A37: First Year Ambassador Program | E37: =sum(B37:D37) -> 0 | I37: =sum(F37:H37) -> 0 | M37: =sum(J37:L37) -> 0 | Q37: =sum(N37:P37) -> 0 | U37: =sum(R37:T37) -> 0 | V37: =sum(E37,I37,M37,Q37,U37) -> 0 | W37: Academics | Y37: 45261 | AB37: FALSE | AC37: FALSE
A38: First Year in Two Years | E38: =sum(B38:D38) -> 0 | I38: =sum(F38:H38) -> 0 | M38: =sum(J38:L38) -> 0 | Q38: =sum(N38:P38) -> 0 | U38: =sum(R38:T38) -> 0 | V38: =sum(E38,I38,M38,Q38,U38) -> 0 | W38: Academics | Y38: 44928 | AB38: FALSE | AC38: FALSE
A39: Fresh Start / Reinstatement | E39: =sum(B39:D39) -> 0 | I39: =sum(F39:H39) -> 0 | M39: =sum(J39:L39) -> 0 | Q39: =sum(N39:P39) -> 0 | U39: =sum(R39:T39) -> 0 | V39: =sum(E39,I39,M39,Q39,U39) -> 0 | W39: Academics | Y39: 44960 | AB39: FALSE | AC39: FALSE
A40: General Academic Advising | E40: =sum(B40:D40) -> 0 | I40: =sum(F40:H40) -> 0 | M40: =sum(J40:L40) -> 0 | Q40: =sum(N40:P40) -> 0 | U40: =sum(R40:T40) -> 0 | V40: =sum(E40,I40,M40,Q40,U40) -> 0 | W40: Academics | Y40: 44989 | AB40: FALSE | AC40: FALSE
